[17/Apr/2014 12:57:32] ERROR [django.request:226] Internal Server Error: /ozio/config/
Traceback (most recent call last):
  File "/Library/Frameworks/Python.framework/Versions/3.3/lib/python3.3/site-packages/django/core/handlers/base.py", line 114, in get_response
    response = wrapped_callback(request, *callback_args, **callback_kwargs)
TypeError: ozio_config() missing 2 required positional arguments: 'obj_name' and 'obj_id'
[17/Apr/2014 13:10:15] ERROR [django.request:226] Internal Server Error: /ozio/config/
Traceback (most recent call last):
  File "/Library/Frameworks/Python.framework/Versions/3.3/lib/python3.3/site-packages/django/core/urlresolvers.py", line 339, in urlconf_module
    return self._urlconf_module
AttributeError: 'RegexURLResolver' object has no attribute '_urlconf_module'

During handling of the above exception, another exception occurred:

Traceback (most recent call last):
  File "/Library/Frameworks/Python.framework/Versions/3.3/lib/python3.3/site-packages/django/core/handlers/base.py", line 101, in get_response
    resolver_match = resolver.resolve(request.path_info)
  File "/Library/Frameworks/Python.framework/Versions/3.3/lib/python3.3/site-packages/django/core/urlresolvers.py", line 318, in resolve
    for pattern in self.url_patterns:
  File "/Library/Frameworks/Python.framework/Versions/3.3/lib/python3.3/site-packages/django/core/urlresolvers.py", line 346, in url_patterns
    patterns = getattr(self.urlconf_module, "urlpatterns", self.urlconf_module)
  File "/Library/Frameworks/Python.framework/Versions/3.3/lib/python3.3/site-packages/django/core/urlresolvers.py", line 341, in urlconf_module
    self._urlconf_module = import_module(self.urlconf_name)
  File "/Library/Frameworks/Python.framework/Versions/3.3/lib/python3.3/importlib/__init__.py", line 90, in import_module
    return _bootstrap._gcd_import(name[level:], package, level)
  File "<frozen importlib._bootstrap>", line 1584, in _gcd_import
  File "<frozen importlib._bootstrap>", line 1565, in _find_and_load
  File "<frozen importlib._bootstrap>", line 1532, in _find_and_load_unlocked
  File "<frozen importlib._bootstrap>", line 584, in _check_name_wrapper
  File "<frozen importlib._bootstrap>", line 1022, in load_module
  File "<frozen importlib._bootstrap>", line 1003, in load_module
  File "<frozen importlib._bootstrap>", line 560, in module_for_loader_wrapper
  File "<frozen importlib._bootstrap>", line 868, in _load_module
  File "<frozen importlib._bootstrap>", line 313, in _call_with_frames_removed
  File "/Users/edwin/Programming/git-repo/edhome/edhome/edhome/urls.py", line 31, in <module>
    url(r'^ozio/', include('ozio.urls', namespace='ozio')),
  File "/Library/Frameworks/Python.framework/Versions/3.3/lib/python3.3/site-packages/django/conf/urls/__init__.py", line 26, in include
    urlconf_module = import_module(urlconf_module)
  File "/Library/Frameworks/Python.framework/Versions/3.3/lib/python3.3/importlib/__init__.py", line 90, in import_module
    return _bootstrap._gcd_import(name[level:], package, level)
  File "<frozen importlib._bootstrap>", line 1584, in _gcd_import
  File "<frozen importlib._bootstrap>", line 1565, in _find_and_load
  File "<frozen importlib._bootstrap>", line 1532, in _find_and_load_unlocked
  File "<frozen importlib._bootstrap>", line 584, in _check_name_wrapper
  File "<frozen importlib._bootstrap>", line 1022, in load_module
  File "<frozen importlib._bootstrap>", line 1003, in load_module
  File "<frozen importlib._bootstrap>", line 560, in module_for_loader_wrapper
  File "<frozen importlib._bootstrap>", line 868, in _load_module
  File "<frozen importlib._bootstrap>", line 313, in _call_with_frames_removed
  File "/Users/edwin/Programming/git-repo/edhome/edhome/ozio/urls.py", line 3, in <module>
    from ozio import views
  File "/Users/edwin/Programming/git-repo/edhome/edhome/ozio/views.py", line 44
    type_form = TypeForm(prefix='type', Type.objects.get(pk=1))
                                           ^
SyntaxError: non-keyword arg after keyword arg
[17/Apr/2014 13:10:20] ERROR [django.request:226] Internal Server Error: /ozio/config/
Traceback (most recent call last):
  File "/Library/Frameworks/Python.framework/Versions/3.3/lib/python3.3/site-packages/django/core/urlresolvers.py", line 339, in urlconf_module
    return self._urlconf_module
AttributeError: 'RegexURLResolver' object has no attribute '_urlconf_module'

During handling of the above exception, another exception occurred:

Traceback (most recent call last):
  File "/Library/Frameworks/Python.framework/Versions/3.3/lib/python3.3/site-packages/django/core/handlers/base.py", line 101, in get_response
    resolver_match = resolver.resolve(request.path_info)
  File "/Library/Frameworks/Python.framework/Versions/3.3/lib/python3.3/site-packages/django/core/urlresolvers.py", line 318, in resolve
    for pattern in self.url_patterns:
  File "/Library/Frameworks/Python.framework/Versions/3.3/lib/python3.3/site-packages/django/core/urlresolvers.py", line 346, in url_patterns
    patterns = getattr(self.urlconf_module, "urlpatterns", self.urlconf_module)
  File "/Library/Frameworks/Python.framework/Versions/3.3/lib/python3.3/site-packages/django/core/urlresolvers.py", line 341, in urlconf_module
    self._urlconf_module = import_module(self.urlconf_name)
  File "/Library/Frameworks/Python.framework/Versions/3.3/lib/python3.3/importlib/__init__.py", line 90, in import_module
    return _bootstrap._gcd_import(name[level:], package, level)
  File "<frozen importlib._bootstrap>", line 1584, in _gcd_import
  File "<frozen importlib._bootstrap>", line 1565, in _find_and_load
  File "<frozen importlib._bootstrap>", line 1532, in _find_and_load_unlocked
  File "<frozen importlib._bootstrap>", line 584, in _check_name_wrapper
  File "<frozen importlib._bootstrap>", line 1022, in load_module
  File "<frozen importlib._bootstrap>", line 1003, in load_module
  File "<frozen importlib._bootstrap>", line 560, in module_for_loader_wrapper
  File "<frozen importlib._bootstrap>", line 868, in _load_module
  File "<frozen importlib._bootstrap>", line 313, in _call_with_frames_removed
  File "/Users/edwin/Programming/git-repo/edhome/edhome/edhome/urls.py", line 31, in <module>
    url(r'^ozio/', include('ozio.urls', namespace='ozio')),
  File "/Library/Frameworks/Python.framework/Versions/3.3/lib/python3.3/site-packages/django/conf/urls/__init__.py", line 26, in include
    urlconf_module = import_module(urlconf_module)
  File "/Library/Frameworks/Python.framework/Versions/3.3/lib/python3.3/importlib/__init__.py", line 90, in import_module
    return _bootstrap._gcd_import(name[level:], package, level)
  File "<frozen importlib._bootstrap>", line 1584, in _gcd_import
  File "<frozen importlib._bootstrap>", line 1565, in _find_and_load
  File "<frozen importlib._bootstrap>", line 1532, in _find_and_load_unlocked
  File "<frozen importlib._bootstrap>", line 584, in _check_name_wrapper
  File "<frozen importlib._bootstrap>", line 1022, in load_module
  File "<frozen importlib._bootstrap>", line 1003, in load_module
  File "<frozen importlib._bootstrap>", line 560, in module_for_loader_wrapper
  File "<frozen importlib._bootstrap>", line 868, in _load_module
  File "<frozen importlib._bootstrap>", line 313, in _call_with_frames_removed
  File "/Users/edwin/Programming/git-repo/edhome/edhome/ozio/urls.py", line 3, in <module>
    from ozio import views
  File "/Users/edwin/Programming/git-repo/edhome/edhome/ozio/views.py", line 44
    type_form = TypeForm(prefix='type', Type.objects.get(pk=1))
                                           ^
SyntaxError: non-keyword arg after keyword arg
