[17/Apr/2014 14:25:17] ERROR [django.request:226] Internal Server Error: /ozio/transaction/
Traceback (most recent call last):
  File "/Library/Frameworks/Python.framework/Versions/3.3/lib/python3.3/site-packages/django/core/handlers/base.py", line 114, in get_response
    response = wrapped_callback(request, *callback_args, **callback_kwargs)
  File "/Users/edwin/Programming/git-repo/edhome/edhome/ozio/views.py", line 44, in ozio_transaction
    outstanding_transactions = Transaction.objects.filter(keyword__exact = 'None')
  File "/Library/Frameworks/Python.framework/Versions/3.3/lib/python3.3/site-packages/django/db/models/manager.py", line 163, in filter
    return self.get_queryset().filter(*args, **kwargs)
  File "/Library/Frameworks/Python.framework/Versions/3.3/lib/python3.3/site-packages/django/db/models/query.py", line 590, in filter
    return self._filter_or_exclude(False, *args, **kwargs)
  File "/Library/Frameworks/Python.framework/Versions/3.3/lib/python3.3/site-packages/django/db/models/query.py", line 608, in _filter_or_exclude
    clone.query.add_q(Q(*args, **kwargs))
  File "/Library/Frameworks/Python.framework/Versions/3.3/lib/python3.3/site-packages/django/db/models/sql/query.py", line 1198, in add_q
    clause = self._add_q(where_part, used_aliases)
  File "/Library/Frameworks/Python.framework/Versions/3.3/lib/python3.3/site-packages/django/db/models/sql/query.py", line 1234, in _add_q
    current_negated=current_negated)
  File "/Library/Frameworks/Python.framework/Versions/3.3/lib/python3.3/site-packages/django/db/models/sql/query.py", line 1122, in build_filter
    lookup_type, value)
  File "/Library/Frameworks/Python.framework/Versions/3.3/lib/python3.3/site-packages/django/db/models/fields/related.py", line 1105, in get_lookup_constraint
    value[index]), AND)
  File "/Library/Frameworks/Python.framework/Versions/3.3/lib/python3.3/site-packages/django/utils/tree.py", line 104, in add
    data = self._prepare_data(data)
  File "/Library/Frameworks/Python.framework/Versions/3.3/lib/python3.3/site-packages/django/db/models/sql/where.py", line 79, in _prepare_data
    value = obj.prepare(lookup_type, value)
  File "/Library/Frameworks/Python.framework/Versions/3.3/lib/python3.3/site-packages/django/db/models/sql/where.py", line 352, in prepare
    return self.field.get_prep_lookup(lookup_type, value)
  File "/Library/Frameworks/Python.framework/Versions/3.3/lib/python3.3/site-packages/django/db/models/fields/__init__.py", line 369, in get_prep_lookup
    return self.get_prep_value(value)
  File "/Library/Frameworks/Python.framework/Versions/3.3/lib/python3.3/site-packages/django/db/models/fields/__init__.py", line 613, in get_prep_value
    return int(value)
ValueError: invalid literal for int() with base 10: 'None'
[17/Apr/2014 14:26:18] ERROR [django.request:226] Internal Server Error: /ozio/transaction/
Traceback (most recent call last):
  File "/Library/Frameworks/Python.framework/Versions/3.3/lib/python3.3/site-packages/django/core/handlers/base.py", line 114, in get_response
    response = wrapped_callback(request, *callback_args, **callback_kwargs)
  File "/Users/edwin/Programming/git-repo/edhome/edhome/ozio/views.py", line 44, in ozio_transaction
    outstanding_transactions = Transaction.objects.filter(keyword__exact = 'NULL')
  File "/Library/Frameworks/Python.framework/Versions/3.3/lib/python3.3/site-packages/django/db/models/manager.py", line 163, in filter
    return self.get_queryset().filter(*args, **kwargs)
  File "/Library/Frameworks/Python.framework/Versions/3.3/lib/python3.3/site-packages/django/db/models/query.py", line 590, in filter
    return self._filter_or_exclude(False, *args, **kwargs)
  File "/Library/Frameworks/Python.framework/Versions/3.3/lib/python3.3/site-packages/django/db/models/query.py", line 608, in _filter_or_exclude
    clone.query.add_q(Q(*args, **kwargs))
  File "/Library/Frameworks/Python.framework/Versions/3.3/lib/python3.3/site-packages/django/db/models/sql/query.py", line 1198, in add_q
    clause = self._add_q(where_part, used_aliases)
  File "/Library/Frameworks/Python.framework/Versions/3.3/lib/python3.3/site-packages/django/db/models/sql/query.py", line 1234, in _add_q
    current_negated=current_negated)
  File "/Library/Frameworks/Python.framework/Versions/3.3/lib/python3.3/site-packages/django/db/models/sql/query.py", line 1122, in build_filter
    lookup_type, value)
  File "/Library/Frameworks/Python.framework/Versions/3.3/lib/python3.3/site-packages/django/db/models/fields/related.py", line 1105, in get_lookup_constraint
    value[index]), AND)
  File "/Library/Frameworks/Python.framework/Versions/3.3/lib/python3.3/site-packages/django/utils/tree.py", line 104, in add
    data = self._prepare_data(data)
  File "/Library/Frameworks/Python.framework/Versions/3.3/lib/python3.3/site-packages/django/db/models/sql/where.py", line 79, in _prepare_data
    value = obj.prepare(lookup_type, value)
  File "/Library/Frameworks/Python.framework/Versions/3.3/lib/python3.3/site-packages/django/db/models/sql/where.py", line 352, in prepare
    return self.field.get_prep_lookup(lookup_type, value)
  File "/Library/Frameworks/Python.framework/Versions/3.3/lib/python3.3/site-packages/django/db/models/fields/__init__.py", line 369, in get_prep_lookup
    return self.get_prep_value(value)
  File "/Library/Frameworks/Python.framework/Versions/3.3/lib/python3.3/site-packages/django/db/models/fields/__init__.py", line 613, in get_prep_value
    return int(value)
ValueError: invalid literal for int() with base 10: 'NULL'
